Workbook

Sheet Summary
C3: Class | D3: P1-A | F3: Closing Dates: | H3: 45975 | J3: NIVEAU: | L3: INFERIEUR | O3: A/S | P3: 2025/2026 | Q3: BULLETIN | S3: 1
D5: 60 | F5: 30 | H5: 80 | J5: 80 | L5: 30 | N5: 80 | P5: =SUM(D5:O5) -> 360
D6: MATHEMATIQUES | F6: ETUDES SOCIALE | H6: KINYARWANDA | J6: ENGLISH | L6: STE | N6: FRANçAIS | Q6: Total | S6: PLACE
B7: NO | C7: NAMES | E7: TOT | F7: CAT | G7: TOT | H7: CAT | I7: TOT | J7: CAT | K7: TOT | L7: CAT | M7: TOT | N7: CAT | O7: TOT | P7: MOYENNE | Q7: Total | R7: MAX | S7: =COUNTA(C8:C53) -> 44
B8: 1 | C8: AGATESI Benita | E8: 32 | G8: 12 | I8: 60 | K8: 30 | M8: 22 | O8: 28 | P8: =+Q8/R8*100 -> 51.111111 | Q8: =+O8+M8+K8+I8+G8+E8 -> 184 | R8: =P5 -> 360 | S8: =RANK(Q8,Q8:Q51) -> 43
B9: 2 | C9: Akeza Lena | E9: 46 | G9: 19 | I9: 72 | K9: 32 | M9: 22 | O9: 28 | P9: =+Q9/R9*100 -> 60.833333 | Q9: =+O9+M9+K9+I9+G9+E9 -> 219 | R9: =P5 -> 360 | S9: =RANK(Q9,Q8:Q51) -> 41
B10: 3 | C10: GAJU Anny | E10: 58 | G10: 25 | I10: 72 | K10: 76 | M10: 25 | O10: 76 | P10: =+Q10/R10*100 -> 92.222222 | Q10: =+O10+M10+K10+I10+G10+E10 -> 332 | R10: =R9 -> 360 | S10: =RANK(Q10,Q8:Q51) -> 11
B11: 4 | C11: GISUBIZO Herve | E11: 60 | G11: 30 | I11: 80 | K11: 80 | M11: 27 | O11: 80 | P11: =+Q11/R11*100 -> 99.166667 | Q11: =+O11+M11+K11+I11+G11+E11 -> 357 | R11: =R10 -> 360 | S11: =RANK(Q11,Q8:Q51) -> 2
B12: 5 | C12: HIRWA Ayman | E12: 43 | G12: 21 | I12: 50 | K12: 30 | M12: 21 | O12: 48 | P12: =+Q12/R12*100 -> 59.166667 | Q12: =+O12+M12+K12+I12+G12+E12 -> 213 | R12: =R11 -> 360 | S12: =RANK(Q12,Q8:Q51) -> 42
B13: 6 | C13: HIRWA Elio Rayan | E13: 56 | G13: 28 | I13: 74 | K13: 80 | M13: 23 | O13: 69 | P13: =+Q13/R13*100 -> 91.666667 | Q13: =+O13+M13+K13+I13+G13+E13 -> 330 | R13: =R12 -> 360 | S13: =RANK(Q13,Q8:Q51) -> 12
B14: 7 | C14: ICYOMORO AGANZE Grayson | E14: 52 | G14: 27 | I14: 68 | K14: 72 | M14: 28 | O14: 53 | P14: =+Q14/R14*100 -> 83.333333 | Q14: =+O14+M14+K14+I14+G14+E14 -> 300 | R14: =R13 -> 360 | S14: =RANK(Q14,Q8:Q52) -> 29
B15: 8 | C15: IHIRWE Lena | E15: 60 | G15: 26 | I15: 80 | K15: 68 | M15: 21 | O15: 62 | P15: =+Q15/R15*100 -> 88.055556 | Q15: =+O15+M15+K15+I15+G15+E15 -> 317 | R15: =R14 -> 360 | S15: =RANK(Q15,Q8:Q52) -> 21
B16: 9 | C16: INEZA Gaella | E16: 48 | G16: 21 | I16: 44 | K16: 40 | M16: 23 | O16: 56 | P16: =+Q16/R16*100 -> 64.444444 | Q16: =+O16+M16+K16+I16+G16+E16 -> 232 | R16: =R15 -> 360 | S16: =RANK(Q16,Q8:Q52) -> 39
B17: 10 | C17: INEZA CYIZERE Daicy | E17: 50 | G17: 19 | I17: 56 | K17: 64 | M17: 21 | O17: 60 | P17: =+Q17/R17*100 -> 75 | Q17: =+O17+M17+K17+I17+G17+E17 -> 270 | R17: =R16 -> 360 | S17: =RANK(Q17,Q8:Q52) -> 36
B18: 11 | C18: IRADUKUNDA INEZA Pamella | E18: 54 | G18: 27 | I18: 76 | K18: 66 | M18: 28 | O18: 66 | P18: =+Q18/R18*100 -> 88.055556 | Q18: =+O18+M18+K18+I18+G18+E18 -> 317 | R18: =R17 -> 360 | S18: =RANK(Q18,Q8:Q52) -> 21
B19: 12 | C19: IRAKOZE Yasipi | E19: 51 | G19: 21 | I19: 66 | K19: 76 | M19: 16 | O19: 68 | P19: =+Q19/R19*100 -> 82.777778 | Q19: =+O19+M19+K19+I19+G19+E19 -> 298 | R19: =R18 -> 360 | S19: =RANK(Q19,Q8:Q52) -> 31
B20: 13 | C20: IRAYASOHOZA SHAMI Baraka | E20: 56 | G20: 22 | I20: 78 | K20: 80 | M20: 20 | O20: 50 | P20: =+Q20/R20*100 -> 85 | Q20: =+O20+M20+K20+I20+G20+E20 -> 306 | R20: =R19 -> 360 | S20: =RANK(Q20,Q8:Q52) -> 25
B21: 14 | C21: IREBE GIKUNDIRO Ella | E21: 59 | G21: 30 | I21: 80 | K21: 80 | M21: 29 | O21: 76 | P21: =+Q21/R21*100 -> 98.333333 | Q21: =+O21+M21+K21+I21+G21+E21 -> 354 | R21: =R20 -> 360 | S21: =RANK(Q21,Q8:Q52) -> 3
B22: 15 | C22: ISHAMI Honnette | E22: 58 | G22: 30 | I22: 74 | K22: 70 | M22: 22 | O22: 64 | P22: =+Q22/R22*100 -> 88.333333 | Q22: =+O22+M22+K22+I22+G22+E22 -> 318 | R22: =R21 -> 360 | S22: =RANK(Q22,Q8:Q52) -> 20
B23: 16 | C23: ISIMBI Tiffah | E23: 44 | G23: 16 | I23: 52 | K23: 68 | M23: 20 | O23: 30 | P23: =+Q23/R23*100 -> 63.888889 | Q23: =+O23+M23+K23+I23+G23+E23 -> 230 | R23: =R22 -> 360 | S23: =RANK(Q23,Q8:Q52) -> 40
B24: 17 | C24: KABANZA IRIHO Arda | E24: 47 | G24: 25 | I24: 74 | K24: 74 | M24: 24 | O24: 60 | P24: =+Q24/R24*100 -> 84.444444 | Q24: =+O24+M24+K24+I24+G24+E24 -> 304 | R24: =R23 -> 360 | S24: =RANK(Q24,Q8:Q52) -> 27
B25: 18 | C25: KAGABA Kevrin | E25: 44 | G25: 19 | I25: 52 | K25: 70 | M25: 28 | O25: 44 | P25: =+Q25/R25*100 -> 71.388889 | Q25: =+O25+M25+K25+I25+G25+E25 -> 257 | R25: =R24 -> 360 | S25: =RANK(Q25,Q8:Q52) -> 37
B26: 19 | C26: KALISA IRIHO Jeyden | E26: 58 | G26: 28 | I26: 80 | K26: 76 | M26: 25 | O26: 58 | P26: =+Q26/R26*100 -> 90.277778 | Q26: =+O26+M26+K26+I26+G26+E26 -> 325 | R26: =R25 -> 360 | S26: =RANK(Q26,Q8:Q52) -> 17
B27: 20 | C27: KEZAKASE Meghan | E27: 60 | G27: 30 | I27: 80 | K27: 72 | M27: 27 | O27: 76 | P27: =+Q27/R27*100 -> 95.833333 | Q27: =+O27+M27+K27+I27+G27+E27 -> 345 | R27: =R26 -> 360 | S27: =RANK(Q27,Q8:Q53) -> 8
B28: 21 | C28: KWIHANGANA Honestly | E28: 58 | G28: 26 | I28: 70 | K28: 68 | M28: 24 | O28: 53 | P28: =+Q28/R28*100 -> 83.055556 | Q28: =+O28+M28+K28+I28+G28+E28 -> 299 | R28: =R27 -> 360 | S28: =RANK(Q28,Q8:Q53) -> 30
B29: 22 | C29: KWIZERA SHYAKA Thibaut | E29: 58 | G29: 24 | I29: 62 | K29: 80 | M29: 27 | O29: 70 | P29: =+Q29/R29*100 -> 89.166667 | Q29: =+O29+M29+K29+I29+G29+E29 -> 321 | R29: =R28 -> 360 | S29: =RANK(Q29,Q8:Q53) -> 19
B30: 23 | C30: MANZI Aime Bonheur | E30: 56 | G30: 19 | I30: 78 | K30: 72 | M30: 20 | O30: 56 | P30: =+Q30/R30*100 -> 83.611111 | Q30: =+O30+M30+K30+I30+G30+E30 -> 301 | R30: =R29 -> 360 | S30: =RANK(Q30,Q8:Q53) -> 28
B31: 24 | C31: MUGISHA Alpha | E31: 60 | G31: 30 | I31: 80 | K31: 80 | M31: 30 | O31: 80 | P31: =+Q31/R31*100 -> 100 | Q31: =+O31+M31+K31+I31+G31+E31 -> 360 | R31: =R30 -> 360 | S31: =RANK(Q31,Q8:Q53) -> 1
B32: 25 | C32: MUHIRWA Junior | E32: 12 | G32: 5 | I32: 12 | K32: 30 | M32: 12 | O32: 10 | P32: =+Q32/R32*100 -> 22.5 | Q32: =+O32+M32+K32+I32+G32+E32 -> 81 | R32: =R31 -> 360 | S32: =RANK(Q32,Q8:Q53) -> 44
B33: 26 | C33: MURAME Saint Liam | E33: 40 | G33: 17 | I33: 58 | K33: 60 | M33: 19 | O33: 42 | P33: =+Q33/R33*100 -> 65.555556 | Q33: =+O33+M33+K33+I33+G33+E33 -> 236 | R33: =R32 -> 360 | S33: =RANK(Q33,Q8:Q53) -> 38
B34: 27 | C34: MURENZI Calvin | E34: 56 | G34: 26 | I34: 72 | K34: 80 | M34: 22 | O34: 70 | P34: =+Q34/R34*100 -> 90.555556 | Q34: =+O34+M34+K34+I34+G34+E34 -> 326 | R34: =R33 -> 360 | S34: =RANK(Q34,Q8:Q53) -> 16
B35: 28 | C35: MURENZI Galvin | E35: 56 | G35: 28 | I35: 80 | K35: 80 | M35: 29 | O35: 80 | P35: =+Q35/R35*100 -> 98.055556 | Q35: =+O35+M35+K35+I35+G35+E35 -> 353 | R35: =R34 -> 360 | S35: =RANK(Q35,Q8:Q43) -> 5
B36: 29 | C36: NGABOYIMANZI Loic | E36: 57 | G36: 25 | I36: 78 | K36: 80 | M36: 21 | O36: 76 | P36: =+Q36/R36*100 -> 93.611111 | Q36: =+O36+M36+K36+I36+G36+E36 -> 337 | R36: =R35 -> 360 | S36: =RANK(Q36,Q8:Q54) -> 10
B37: 30 | C37: NIYIBIKORA Jehovanie | E37: 58 | G37: 20 | I37: 80 | K37: 74 | M37: 28 | O37: 70 | P37: =+Q37/R37*100 -> 91.666667 | Q37: =+O37+M37+K37+I37+G37+E37 -> 330 | R37: =R36 -> 360 | S37: =RANK(Q37,Q8:Q54) -> 12
B38: 31 | C38: NTIRIKINA Yvan Luc | E38: 56 | G38: 28 | I38: 80 | K38: 68 | M38: 22 | O38: 55 | P38: =+Q38/R38*100 -> 85.833333 | Q38: =+O38+M38+K38+I38+G38+E38 -> 309 | R38: =R37 -> 360 | S38: =RANK(Q38,Q8:Q54) -> 23
B39: 32 | C39: NTWARI Charmant | E39: 60 | G39: 26 | I39: 80 | K39: 76 | M39: 22 | O39: 64 | P39: =+Q39/R39*100 -> 91.111111 | Q39: =+O39+M39+K39+I39+G39+E39 -> 328 | R39: =R38 -> 360 | S39: =RANK(Q39,Q8:Q54) -> 14
B40: 33 | C40: NTWARI Lucky Blaise | E40: 50 | G40: 27 | I40: 66 | K40: 58 | M40: 26 | O40: 65 | P40: =+Q40/R40*100 -> 81.111111 | Q40: =+O40+M40+K40+I40+G40+E40 -> 292 | R40: =R39 -> 360 | S40: =RANK(Q40,Q8:Q54) -> 32
B41: 34 | C41: NUTETE UTUJE Israa | E41: 60 | G41: 30 | I41: 80 | K41: 80 | M41: 28 | O41: 76 | P41: =+Q41/R41*100 -> 98.333333 | Q41: =+O41+M41+K41+I41+G41+E41 -> 354 | R41: =R40 -> 360 | S41: =RANK(Q41,Q8:Q54) -> 3
B42: 35 | C42: NUWAYO ISHEJA Bella | E42: 60 | G42: 23 | I42: 78 | K42: 80 | M42: 26 | O42: 58 | P42: =+Q42/R42*100 -> 90.277778 | Q42: =+O42+M42+K42+I42+G42+E42 -> 325 | R42: =R41 -> 360 | S42: =RANK(Q42,Q8:Q54) -> 17
B43: 36 | C43: SHAMI Blaise | E43: 48 | G43: 21 | I43: 74 | K43: 70 | M43: 15 | O43: 50 | P43: =+Q43/R43*100 -> 77.222222 | Q43: =+O43+M43+K43+I43+G43+E43 -> 278 | R43: =R42 -> 360 | S43: =RANK(Q43,Q8:Q54) -> 35
...

Sheet PROCRA
B1: P1B
A2: PLACE | B2: NAMES | C2: MOYENNE
A3: =Summary!S14 -> 29 | B3: =Summary!C14 -> ICYOMORO AGANZE Grayson | C3: =Summary!P14 -> 83.333333
A4: =Summary!S10 -> 11 | B4: =Summary!C10 -> GAJU Anny | C4: =Summary!P10 -> 92.222222
A5: =Summary!S17 -> 36 | B5: =Summary!C17 -> INEZA CYIZERE Daicy | C5: =Summary!P17 -> 75
A6: =Summary!S33 -> 38 | B6: =Summary!C33 -> MURAME Saint Liam | C6: =Summary!P33 -> 65.555556
A7: =Summary!S29 -> 19 | B7: =Summary!C29 -> KWIZERA SHYAKA Thibaut | C7: =Summary!P29 -> 89.166667
A8: =Summary!S12 -> 42 | B8: =Summary!C12 -> HIRWA Ayman | C8: =Summary!P12 -> 59.166667
A9: =Summary!S43 -> 35 | B9: =Summary!C43 -> SHAMI Blaise | C9: =Summary!P43 -> 77.222222
A10: =Summary!S27 -> 8 | B10: =Summary!C27 -> KEZAKASE Meghan | C10: =Summary!P27 -> 95.833333
A11: =Summary!S25 -> 37 | B11: =Summary!C25 -> KAGABA Kevrin | C11: =Summary!P25 -> 71.388889
A12: =Summary!S48 -> 15 | B12: =Summary!C48 -> UMURERWA Believe | C12: =Summary!P48 -> 90.833333
A13: =Summary!S36 -> 10 | B13: =Summary!C36 -> NGABOYIMANZI Loic | C13: =Summary!P36 -> 93.611111
A14: =Summary!S40 -> 32 | B14: =Summary!C40 -> NTWARI Lucky Blaise | C14: =Summary!P40 -> 81.111111
A15: =Summary!S41 -> 3 | B15: =Summary!C41 -> NUTETE UTUJE Israa | C15: =Summary!P41 -> 98.333333
A16: =Summary!S52 -> 45 | B16: =Summary!C52 -> 0 | C16: =Summary!P52 -> 0
A17: =Summary!S49 -> 34 | B17: =Summary!C49 -> UMWIZA IKIREZI Daisy | C17: =Summary!P49 -> 80.833333
A18: =Summary!S46 -> 26 | B18: =Summary!C46 -> TETERO NIMWIZA Iris | C18: =Summary!P46 -> 84.722222
A19: =Summary!S39 -> 14 | B19: =Summary!C39 -> NTWARI Charmant | C19: =Summary!P39 -> 91.111111
A20: =Summary!S35 -> 5 | B20: =Summary!C35 -> MURENZI Galvin | C20: =Summary!P35 -> 98.055556
A21: =Summary!S24 -> 27 | B21: =Summary!C24 -> KABANZA IRIHO Arda | C21: =Summary!P24 -> 84.444444
A22: =Summary!S30 -> 28 | B22: =Summary!C30 -> MANZI Aime Bonheur | C22: =Summary!P30 -> 83.611111
A23: =Summary!S42 -> 17 | B23: =Summary!C42 -> NUWAYO ISHEJA Bella | C23: =Summary!P42 -> 90.277778
A24: =Summary!S44 -> 6 | B24: =Summary!C44 -> Shema Christe Estella | C24: =Summary!P44 -> 96.944444
A25: =Summary!S18 -> 21 | B25: =Summary!C18 -> IRADUKUNDA INEZA Pamella | C25: =Summary!P18 -> 88.055556
A26: =Summary!S20 -> 25 | B26: =Summary!C20 -> IRAYASOHOZA SHAMI Baraka | C26: =Summary!P20 -> 85
A27: =Summary!S19 -> 31 | B27: =Summary!C19 -> IRAKOZE Yasipi | C27: =Summary!P19 -> 82.777778
A28: =Summary!S32 -> 44 | B28: =Summary!C32 -> MUHIRWA Junior | C28: =Summary!P32 -> 22.5
A29: =Summary!S8 -> 43 | B29: =Summary!C8 -> AGATESI Benita | C29: =Summary!P8 -> 51.111111
A30: =Summary!S34 -> 16 | B30: =Summary!C34 -> MURENZI Calvin | C30: =Summary!P34 -> 90.555556
A31: =Summary!S47 -> 23 | B31: =Summary!C47 -> UMULISA Promesse | C31: =Summary!P47 -> 85.833333
A32: =Summary!S13 -> 12 | B32: =Summary!C13 -> HIRWA Elio Rayan | C32: =Summary!P13 -> 91.666667
A33: =Summary!S26 -> 17 | B33: =Summary!C26 -> KALISA IRIHO Jeyden | C33: =Summary!P26 -> 90.277778
A34: =Summary!S53 -> 45 | B34: =Summary!C53 -> 0 | C34: =Summary!P53 -> 0
A35: =Summary!S38 -> 23 | B35: =Summary!C38 -> NTIRIKINA Yvan Luc | C35: =Summary!P38 -> 85.833333
A36: =Summary!S31 -> 1 | B36: =Summary!C31 -> MUGISHA Alpha | C36: =Summary!P31 -> 100
A37: =Summary!S23 -> 40 | B37: =Summary!C23 -> ISIMBI Tiffah | C37: =Summary!P23 -> 63.888889
A38: =Summary!S37 -> 12 | B38: =Summary!C37 -> NIYIBIKORA Jehovanie | C38: =Summary!P37 -> 91.666667
A39: =Summary!S45 -> 7 | B39: =Summary!C45 -> SIBO JABO Besnik | C39: =Summary!P45 -> 96.111111
A40: =Summary!S28 -> 30 | B40: =Summary!C28 -> KWIHANGANA Honestly | C40: =Summary!P28 -> 83.055556
...

Sheet P1A
B6: REPUBLIQUE DU RWANDA | D6: A/S: | E6: =Summary!P3 -> 2025/2026 | G6: REPUBLIQUE DU RWANDA | I6: A/S: | J6: =E6 -> 2025/2026
B7: MINISTERE DE L’EDUCATION | G7: MINISTERE DE L’EDUCATION
B8: VILLE DE KIGALI | D8: CLASSE: | E8: =Summary!D3 -> P1-A | G8: VILLE DE KIGALI | I8: CLASSE: | J8: =E8 -> P1-A
B9: DISTRICT DE NYARUGENGE | G9: DISTRICT DE NYARUGENGE
B10: SECTEUR NYAMIRAMBO | G10: SECTEUR NYAMIRAMBO
B11: JERICHO SCHOOL | D11: NIVEAU: | E11: =Summary!L3 -> INFERIEUR | G11: JERICHO SCHOOL | I11: NIVEAU: | J11: =E11 -> INFERIEUR
B12: TEL: 0788695562 | G12: TEL: 0788695562
B13: EMAIL: jericho.school@yahoo.fr | G13: EMAIL: jericho.school@yahoo.fr
C15: BULLETIN SCOLAIRE | H15: BULLETIN SCOLAIRE
B16: NOMS: | C16: =Summary!C8 -> AGATESI Benita | G16: NOMS: | H16: =Summary!C9 -> Akeza Lena
B17: COURS | C17: MI -TRIMESTRE | G17: COURS | H17: MI -TRIMESTRE
C18: MAX | D18: POINTS | H18: MAX | I18: POINTS
B19: MATHEMATIQUES | C19: =Summary!D5 -> 60 | D19: =Summary!E8 -> 32 | G19: MATHEMATIQUES | H19: =C19 -> 60 | I19: =Summary!E9 -> 46
B20: ETUDES SOCIALES | C20: =Summary!F5 -> 30 | D20: =Summary!G8 -> 12 | G20: ETUDES SOCIALES | H20: =C20 -> 30 | I20: =Summary!G9 -> 19
B21: KINYARWANDA | C21: =Summary!H5 -> 80 | D21: =Summary!I8 -> 60 | G21: KINYARWANDA | H21: =C21 -> 80 | I21: =Summary!I9 -> 72
B22: ENGLISH | C22: =Summary!J5 -> 80 | D22: =Summary!K8 -> 30 | G22: ENGLISH | H22: =C22 -> 80 | I22: =Summary!K9 -> 32
B23: STE | C23: =Summary!L5 -> 30 | D23: =Summary!M8 -> 22 | G23: STE | H23: =C23 -> 30 | I23: =Summary!M9 -> 22
B24: FRANçAIS | C24: =Summary!N5 -> 80 | D24: =Summary!O8 -> 28 | G24: FRANçAIS | H24: =C24 -> 80 | I24: =Summary!O9 -> 28
B25: TOTAL | C25: =SUM(C19:C24) -> 360 | D25: =SUM(D19:D24) -> 184 | G25: TOTAL | H25: =SUM(H19:H24) -> 360 | I25: =SUM(I19:I24) -> 219
B26: POURCENTAGE | C26: =D25/C25 -> 0.51111111 | G26: POURCENTAGE | H26: =I25/H25 -> 0.60833333
B27: PLACE | C27: =Summary!S8 -> 43 | D27: =Summary!S7 -> 44 | G27: PLACE | H27: =Summary!S9 -> 41 | I27: =Summary!S7 -> 44
B28: SIGNATURE DES PARENTS | G28: SIGNATURE DES PARENTS
B29: SIGNATURE DU TITULAIRE | G29: SIGNATURE DU TITULAIRE
B31: FAIT A JERICHO SCHOOL | G31: FAIT A JERICHO SCHOOL
B32: DATE | C32: =Summary!H3 -> 45975 | G32: DATE | H32: =C32 -> 45975
B42: REPUBLIQUE DU RWANDA | D42: A/S: | E42: =E6 -> 2025/2026 | G42: REPUBLIQUE DU RWANDA | I42: A/S: | J42: =E42 -> 2025/2026
B43: MINISTERE DE L’EDUCATION | G43: MINISTERE DE L’EDUCATION
B44: VILLE DE KIGALI | D44: CLASSE: | E44: =E8 -> P1-A | G44: VILLE DE KIGALI | I44: CLASSE: | J44: =E44 -> P1-A
B45: DISTRICT DE NYARUGENGE | G45: DISTRICT DE NYARUGENGE
B46: SECTEUR NYAMIRAMBO | G46: SECTEUR NYAMIRAMBO
B47: JERICHO SCHOOL | D47: NIVEAU: | E47: =E11 -> INFERIEUR | G47: JERICHO SCHOOL | I47: NIVEAU: | J47: =E47 -> INFERIEUR
B48: TEL: 0788695562 | G48: TEL: 0788695562
B49: EMAIL: jericho.school@yahoo.fr | G49: EMAIL: jericho.school@yahoo.fr
C51: BULLETIN SCOLAIRE | H51: BULLETIN SCOLAIRE
B52: NOMS: | C52: =Summary!C10 -> GAJU Anny | G52: NOMS: | H52: =Summary!C11 -> GISUBIZO Herve
B53: COURS | C53: MI -TRIMESTRE | G53: COURS | H53: MI -TRIMESTRE
C54: MAX | D54: POINTS | H54: MAX | I54: POINTS
B55: MATHEMATIQUES | C55: =C19 -> 60 | D55: =Summary!E10 -> 58 | G55: MATHEMATIQUES | H55: =C55 -> 60 | I55: =Summary!E11 -> 60
B56: ETUDES SOCIALES | C56: =C20 -> 30 | D56: =Summary!G10 -> 25 | G56: ETUDES SOCIALES | H56: =C56 -> 30 | I56: =Summary!G11 -> 30
B57: KINYARWANDA | C57: =C21 -> 80 | D57: =Summary!I10 -> 72 | G57: KINYARWANDA | H57: =C57 -> 80 | I57: =Summary!I11 -> 80
...
